Workbook

Sheet Summary
A1: Science question review (Biology, Chemistry, Physics; AQA and Edexcel; separate and Combined Science)
A2: How to fill in: on each subject sheet, choose a value in the yellow "Rob's decision" column: Use suggested fix, Keep as is, Remove, or I'll edit (put your wording in "Rob's note"). Then upload the file back to review/ with the same name.
A3: Method: every question was reviewed by an independent reviewer, pack by pack, against the specification text; every numerical answer (found by its content, not the Calc tag) was recalculated with a script (tools/review/calc_check.py). Only flagged questions are listed, Wrong first, then Doubtful, then Minor.
A4: Specifications used: AQA 8461 Biology, version 1.0 (21 April 2016); AQA 8462 Chemistry, version 1.1 (4 October 2019); AQA 8463 Physics, version 1.1 (30 September 2019); AQA 8464 Combined Science: Trilogy, version 1.1 (4 October 2019); Edexcel 1BI0 Biology, 1CH0 Chemistry and 1PH0 Physics, Issue 4; Edexcel 1SC0 Combined Science, Issue 6.
A5: Question, reviewed and recalculated counts are counted from the packs and review files (hardcoded); flag counts are formulas over the subject sheets.
A7: Subject | B7: Board | C7: Questions | D7: Reviewed | E7: Recalculated | F7: Wrong | G7: Doubtful | H7: Minor | I7: All flags
A8: Biology | B8: AQA | C8: 414 | D8: 414 | E8: 19 | F8: =COUNTIFS(Biology!$B$2:$B$2000,$B8,Biology!$K$2:$K$2000,"Wrong") | G8: =COUNTIFS(Biology!$B$2:$B$2000,$B8,Biology!$K$2:$K$2000,"Doubtful") | H8: =COUNTIFS(Biology!$B$2:$B$2000,$B8,Biology!$K$2:$K$2000,"Minor") | I8: =SUM(F8:H8)
A9: Biology | B9: Edexcel | C9: 597 | D9: 597 | E9: 50 | F9: =COUNTIFS(Biology!$B$2:$B$2000,$B9,Biology!$K$2:$K$2000,"Wrong") | G9: =COUNTIFS(Biology!$B$2:$B$2000,$B9,Biology!$K$2:$K$2000,"Doubtful") | H9: =COUNTIFS(Biology!$B$2:$B$2000,$B9,Biology!$K$2:$K$2000,"Minor") | I9: =SUM(F9:H9)
A10: Chemistry | B10: AQA | C10: 592 | D10: 592 | E10: 47 | F10: =COUNTIFS(Chemistry!$B$2:$B$2000,$B10,Chemistry!$K$2:$K$2000,"Wrong") | G10: =COUNTIFS(Chemistry!$B$2:$B$2000,$B10,Chemistry!$K$2:$K$2000,"Doubtful") | H10: =COUNTIFS(Chemistry!$B$2:$B$2000,$B10,Chemistry!$K$2:$K$2000,"Minor") | I10: =SUM(F10:H10)
A11: Chemistry | B11: Edexcel | C11: 845 | D11: 845 | E11: 67 | F11: =COUNTIFS(Chemistry!$B$2:$B$2000,$B11,Chemistry!$K$2:$K$2000,"Wrong") | G11: =COUNTIFS(Chemistry!$B$2:$B$2000,$B11,Chemistry!$K$2:$K$2000,"Doubtful") | H11: =COUNTIFS(Chemistry!$B$2:$B$2000,$B11,Chemistry!$K$2:$K$2000,"Minor") | I11: =SUM(F11:H11)
A12: Physics | B12: AQA | C12: 475 | D12: 475 | E12: 81 | F12: =COUNTIFS(Physics!$B$2:$B$2000,$B12,Physics!$K$2:$K$2000,"Wrong") | G12: =COUNTIFS(Physics!$B$2:$B$2000,$B12,Physics!$K$2:$K$2000,"Doubtful") | H12: =COUNTIFS(Physics!$B$2:$B$2000,$B12,Physics!$K$2:$K$2000,"Minor") | I12: =SUM(F12:H12)
A13: Physics | B13: Edexcel | C13: 1127 | D13: 1127 | E13: 204 | F13: =COUNTIFS(Physics!$B$2:$B$2000,$B13,Physics!$K$2:$K$2000,"Wrong") | G13: =COUNTIFS(Physics!$B$2:$B$2000,$B13,Physics!$K$2:$K$2000,"Doubtful") | H13: =COUNTIFS(Physics!$B$2:$B$2000,$B13,Physics!$K$2:$K$2000,"Minor") | I13: =SUM(F13:H13)
A14: Total | C14: =SUM(C8:C13) | D14: =SUM(D8:D13) | E14: =SUM(E8:E13) | F14: =SUM(F8:F13) | G14: =SUM(G8:G13) | H14: =SUM(H8:H13) | I14: =SUM(I8:I13)

Sheet Biology
A1: ID | B1: Board | C1: Subject | D1: Course | E1: Tier | F1: Topic | G1: Spec ref | H1: Question | I1: Answer | J1: Accepted answers | K1: Grade | L1: Reason | M1: Suggested fix | N1: Rob's decision | O1: Rob's note
A2: edexcel-bio-5-018 | B2: Edexcel | C2: Biology | D2: Separate and Combined | E2: Both | F2: Health, disease and the development of medicines | G2: 5.5 | H2: Which bacterium causes stomach ulcers? | I2: Helicobacter | J2: Helicobacter pylori; H. pylori | K2: Wrong | L2: Helicobacter and stomach ulcers is spec point 5.5fB, which is separate science only; it is not in 1SC0 5.5, but the question is tagged Separate and Combined (combRef 5.5). | M2: Change course to Separate only (ref 5.5fB / 5.5, combRef blank).
A3: edexcel-bio-5-019 | B3: Edexcel | C3: Biology | D3: Separate and Combined | E3: Both | F3: Health, disease and the development of medicines | G3: 5.5 | H3: Ebola is caused by a virus. Name the type of illness it causes. | I3: Haemorrhagic fever | J3: Hemorrhagic fever | K3: Wrong | L3: Ebola is spec point 5.5gB, which is separate science only and not in 1SC0, but the question is tagged Separate and Combined (combRef 5.5). | M3: Change course to Separate only (combRef blank).
A4: edexcel-bio-5-025 | B4: Edexcel | C4: Biology | D4: Separate and Combined | E4: Both | F4: Health, disease and the development of medicines | G4: 5.6 | H4: Why must healthcare workers treating Ebola patients wear full protective clothing? | I4: Ebola spreads through body fluids | J4: Spread by body fluids; avoid contact with body fluids | K4: Wrong | L4: Ebola spread by body fluids is spec point 5.6fB, separate science only and absent from 1SC0, but the question is tagged Separate and Combined (combRef 5.6). Also hexOk is true on an explanation question. | M4: Change course to Separate only (combRef blank); set hexOk false.
A5: edexcel-bio-7-029 | B5: Edexcel | C5: Biology | D5: Separate and Combined | E5: Both | F5: Animal coordination, control and homeostasis | G5: 7.9 | H5: Name the three internal conditions controlled by homeostasis at GCSE. | I5: Body temperature, blood glucose, water content | J5: Temperature, blood sugar and water levels; Temperature, blood glucose concentration and water | K5: Doubtful | L5: Combined Science (1SC0) does not include thermoregulation or osmoregulation (7.10B–7.12B, 7.18B–7.22B are separate only; 1SC0 says so after 7.9), so asking Combined students for 'the three conditions controlled at GCSE' goes beyond their course. Also hexOk is true but the three can be listed in any order. | M5: Tag Separate only, or reword for Combined (e.g. ask for one condition kept constant) and set hexOk false.
A6: aqa-bio-4.1-006 | B6: AQA | C6: Biology | D6: Separate and Combined | E6: Both | F6: Cell biology | G6: 4.1.1.2 | H6: A light microscope has a ×10 eyepiece lens and a ×40 objective lens. What is the total magnification? | I6: ×400 | J6: 400; 400 times | K6: Minor | L6: Multiplication calculation (10 x 40) but calcTag is false. | M6: Set calcTag true.
A7: aqa-bio-4.1-008 | B7: AQA | C7: Biology | D7: Separate and Combined | E7: Both | F7: Cell biology | G7: 4.1.1.2 | H7: Apart from labels, what must a drawing of cells from the light microscope practical include? | I7: Magnification scale | J7: Scale bar; Magnification; Scale | K7: Minor | L7: hexOk is true with letter M, but a common correct answer is 'scale bar' (S), which is also in the accepted list. | M7: Set hexOk false, or keep answer as 'Scale' family consistently.
A8: aqa-bio-4.1-009 | B8: AQA | C8: Biology | D8: Separate and Combined | E8: Both | F8: Cell biology | G8: 4.1.1.2 | H8: Why is a layer of onion epidermis only one cell thick used on a microscope slide? | I8: Light can pass through it | J8: So light passes through; Cells do not overlap | K8: Minor | L8: Open 'why' question with hexOk true: correct answers start variously ('So light...', 'Thin enough...', 'Cells don't overlap'). | M8: Set hexOk false.
A9: aqa-bio-4.1-015 | B9: AQA | C9: Biology | D9: Separate and Combined | E9: Both | F9: Cell biology | G9: 4.1.1.4 | H9: How does the ability of many plant cells to differentiate differ from that of most animal cells? | I9: Plant cells differentiate throughout life | J9: Plant cells keep the ability to differentiate; Animal cells only differentiate early | K9: Minor | L9: hexOk true (P), but students will often answer 'Throughout life' or 'They keep the ability...' or start with 'Animal cells...'. | M9: Set hexOk false; accept 'Plants can differentiate throughout life'.
A10: aqa-bio-4.1-017 | B10: AQA | C10: Biology | D10: Separate and Combined | E10: Both | F10: Cell biology | G10: 4.1.1.5 | H10: An image of a cell is 50 mm wide and the real cell is 0.5 mm wide. What is the magnification? | I10: ×100 | J10: 100; 100 times | K10: Minor | L10: Magnification calculation (50 / 0.5) but calcTag is false. | M10: Set calcTag true.
A11: aqa-bio-4.1-020 | B11: AQA | C11: Biology | D11: Separate only | E11: Both | F11: Cell biology | G11: 4.1.1.6 | H11: Why are cultures in school laboratories generally incubated at 25 °C? | I11: Reduces growth of harmful pathogens | J11: Pathogens less likely to grow; Human pathogens grow best at 37 °C | K11: Minor | L11: hexOk true (R for 'Reduces'), but common correct answers start differently ('Less likely pathogens grow', 'Pathogens...', 'Safety'). | M11: Set hexOk false.
A12: aqa-bio-4.1-022 | B12: AQA | C12: Biology | D12: Separate only | E12: Higher only | F12: Cell biology | G12: 4.1.1.6 | H12: A population of 5 × 10⁶ bacteria doubles twice. How many bacteria are there now, in standard form? | I12: 2 × 10⁷ | J12: 2 x 10^7 | K12: Minor | L12: Calculation (5 x 10^6 x 4) but calcTag is false. | M12: Set calcTag true.
A13: aqa-bio-4.1-034 | B13: AQA | C13: Biology | D13: Separate and Combined | E13: Both | F13: Cell biology | G13: 4.1.2.3 | H13: Apart from ethical or religious objections, state one risk of using stem cells in medicine. | I13: Transfer of viral infection | J13: Viral infection; Passing on a virus | K13: Minor | L13: hexOk true (T for 'Transfer'), but the accepted 'Viral infection' starts with V; students may also give 'tumours/cancer', a valid risk not accepted. | M13: Set hexOk false; consider accepting 'Infection'.
... A51: aqa-bio-4.4-015 | B51: AQA | C51: Biology | D51: Separate and Combined | E51: Both | F51: Bioenergetics | G51: 4.4.1.2 | H51: In the pondweed practical, why might a beaker of water be placed between the lamp and the pondweed? | I51: Keep the temperature constant | J51: Absorbs heat from the lamp; Stops the water heating up; Temperature is a control variable | K51: Minor | L51: hexOk is true but accepted answers start with A, S, T ('Absorbs heat...', 'Stops the water heating up', 'Temperature...'). | M51: Set hexOk false.
A52: aqa-bio-4.4-018 | B52: AQA | C52: Biology | D52: Separate and Combined | E52: Both | F52: Bioenergetics | G52: 4.4.1.3 | H52: Which substance, made from glucose, strengthens plant cell walls? | I52: Cellulose | K52: Minor | L52: Near-duplicate of aqa-bio-4.1-049 ('Which substance in plant cell walls strengthens the cell?' - Cellulose) in the same subject. | M52: Remove, or reword to a different use of glucose (e.g. 'Plants convert glucose into which substances for storage in seeds?' - Fats or oils).
A53: aqa-bio-4.4-020 | B53: AQA | C53: Biology | D53: Separate and Combined | E53: Both | F53: Bioenergetics | G53: 4.4.1.3 | H53: Why do plants store glucose as starch rather than as glucose itself? | I53: Starch is insoluble | J53: Insoluble, so it does not affect osmosis; Does not affect water movement into cells | K53: Minor | L53: hexOk is true but accepted 'Insoluble, so...' and 'Does not affect water movement' start with I and D. | M53: Set hexOk false.
A54: aqa-bio-4.4-022 | B54: AQA | C54: Biology | D54: Separate and Combined | E54: Both | F54: Bioenergetics | G54: 4.4.2.1 | H54: Write the word equation for aerobic respiration. | I54: Glucose + oxygen → carbon dioxide + water | J54: C₆H₁₂O₆ + O₂ → CO₂ + H₂O; C₆H₁₂O₆ + 6O₂ → 6CO₂ + 6H₂O | K54: Minor | L54: A word equation is asked for, yet an unbalanced symbol equation (C6H12O6 + O2 -> CO2 + H2O) is accepted. | M54: Remove the unbalanced symbol equation from the accepted answers.
A55: aqa-bio-4.4-026 | B55: AQA | C55: Biology | D55: Separate and Combined | E55: Both | F55: Bioenergetics | G55: 4.4.2.1 | H55: Why does anaerobic respiration transfer much less energy than aerobic respiration? | I55: Incomplete oxidation of glucose | J55: Glucose is not fully oxidised; Glucose is only partly broken down | K55: Minor | L55: hexOk is true but accepted 'Glucose is not fully oxidised' starts with G. | M55: Set hexOk false.
A56: aqa-bio-4.4-028 | B56: AQA | C56: Biology | D56: Separate and Combined | E56: Both | F56: Bioenergetics | G56: 4.4.2.1 | H56: Organisms use energy from respiration for movement, for keeping warm and for chemical reactions that build what? | I56: Larger molecules | J56: Large molecules; Bigger molecules; New molecules | K56: Minor | L56: hexOk is true but accepted 'Bigger molecules' and 'New molecules' start with B and N. | M56: Set hexOk false, or drop those accepted forms.
A57: aqa-bio-4.4-029 | B57: AQA | C57: Biology | D57: Separate and Combined | E57: Both | F57: Bioenergetics | G57: 4.4.2.2 | H57: During exercise, heart rate and breathing rate rise. Which other breathing measurement increases so more oxygen is taken in? | I57: Breath volume | J57: Depth of breathing; Volume of each breath; Tidal volume; Deeper breaths | K57: Minor | L57: hexOk is true but accepted 'Depth of breathing', 'Volume of each breath', 'Tidal volume', 'Deeper breaths' start with other letters. | M57: Set hexOk false.
A58: aqa-bio-4.5-003 | B58: AQA | C58: Biology | D58: Separate and Combined | E58: Both | F58: Homeostasis and response | G58: 4.5.1 | H58: Name the two types of effector in a control system. | I58: Muscles and glands | J58: Muscle and gland; Glands and muscles | K58: Minor | L58: hexOk is true but accepted 'Glands and muscles' starts with G. The items can be given in any order. | M58: Set hexOk false.
A59: aqa-bio-4.5-004 | B59: AQA | C59: Biology | D59: Separate and Combined | E59: Both | F59: Homeostasis and response | G59: 4.5.1 | H59: Name the three internal conditions in the human body that homeostasis controls. | I59: Blood glucose, body temperature, water levels | J59: Blood sugar, temperature, water; Glucose, temperature, water | K59: Minor | L59: hexOk is true but a correct answer can start with B/G, T or W. The items can be given in any order. | M59: Set hexOk false.
A60: aqa-bio-4.5-006 | B60: AQA | C60: Biology | D60: Separate and Combined | E60: Both | F60: Homeostasis and response | G60: 4.5.1 | H60: Why must homeostasis keep body temperature close to its normal value? | I60: Optimum temperature for enzyme action | J60: Enzymes work best; Enzymes would denature if too hot; Optimum conditions for enzymes | K60: Minor | L60: hexOk is true but accepted 'Enzymes work best...' and 'Enzymes would denature...' start with E. | M60: Set hexOk false.
A61: aqa-bio-4.5-009 | B61: AQA | C61: Biology | D61: Separate and Combined | E61: Both | F61: Homeostasis and response | G61: 4.5.2.1 (Combined 4.5.2) | H61: How does a nerve signal cross a synapse? | I61: Chemical diffuses across the gap | J61: Diffusion of a chemical; Chemical diffuses across; Neurotransmitter diffuses across | K61: Minor | L61: hexOk is true but accepted 'Diffusion of a chemical' and 'Neurotransmitter diffuses across' start with D and N. | M61: Set hexOk false.
A62: aqa-bio-4.5-012 | B62: AQA | C62: Biology | D62: Separate and Combined | E62: Both | F62: Homeostasis and response | G62: 4.5.2.1 (Combined 4.5.2) | H62: A student tests whether drinking caffeine affects reaction time. What is the independent variable? | I62: Caffeine | J62: Amount of caffeine; Caffeine intake; Caffeine drunk | K62: Minor | L62: hexOk is true but accepted 'Amount of caffeine' starts with A. | M62: Set hexOk false.
A63: aqa-bio-4.5-021 | B63: AQA | C63: Biology | D63: Separate only | E63: Both | F63: Homeostasis and response | G63: 4.5.2.3 | H63: What is accommodation in the eye? | I63: Changing lens shape to focus | J63: Changing the shape of the lens; Lens changes shape to focus | K63: Minor | L63: hexOk is true but accepted 'Lens changes shape to focus' starts with L. | M63: Set hexOk false.
A64: aqa-bio-4.5-022 | B64: AQA | C64: Biology | D64: Separate only | E64: Both | F64: Homeostasis and response | G64: 4.5.2.3 | H64: To focus on a near object, what do the ciliary muscles do? | I64: Contract | J64: They contract; Ciliary muscles contract | K64: Minor | L64: hexOk is true but accepted 'They contract' starts with T (first significant word 'They'). | M64: Set hexOk false, or remove 'They contract' from accepted answers.
... A67: aqa-bio-4.5-030 | B67: AQA | C67: Biology | D67: Separate and Combined | E67: Both | F67: Homeostasis and response | G67: 4.5.3.1 | H67: How are hormones carried to their target organs? | I67: In the bloodstream | J67: Blood; By the blood; In the blood plasma | K67: Minor | L67: hexOk is true but the stored answer starts 'In' (letter I) while accepted 'Blood' / 'By the blood' start with B. | M67: Set hexOk false, or make the answer 'Blood'.
A68: aqa-bio-4.5-034 | B68: AQA | C68: Biology | D68: Separate and Combined | E68: Both | F68: Homeostasis and response | G68: 4.5.3.2 | H68: In liver and muscle cells, what is excess glucose converted to for storage? | I68: Glycogen | K68: Minor | L68: Near-duplicate of aqa-bio-4.4-037 ('Animals convert excess glucose into which storage carbohydrate?' - Glycogen) in the same subject. | M68: Remove one of the pair, or reword this one (e.g. 'In which two types of cell is glycogen stored?' - Liver and muscle cells).
A69: aqa-bio-4.5-036 | B69: AQA | C69: Biology | D69: Separate and Combined | E69: Both | F69: Homeostasis and response | G69: 4.5.3.2 | H69: After a meal, why does blood glucose stay high for longer in someone with Type 1 diabetes? | I69: Pancreas makes too little insulin | J69: Not enough insulin produced; No insulin made | K69: Minor | L69: hexOk is true but accepted 'Not enough insulin produced' and 'No insulin made' start with N. | M69: Set hexOk false.
A70: aqa-bio-4.5-039 | B70: AQA | C70: Biology | D70: Separate only | E70: Both | F70: Homeostasis and response | G70: 4.5.3.3 | H70: The kidneys make urine by filtering the blood and then by what process? | I70: Selective reabsorption | J70: Reabsorption | K70: Minor | L70: hexOk is true but accepted 'Reabsorption' starts with R. | M70: Set hexOk false.
A71: aqa-bio-4.5-040 | B71: AQA | C71: Biology | D71: Separate only | E71: Both | F71: Homeostasis and response | G71: 4.5.3.3 | H71: Name the treatment for kidney failure that uses a machine to remove urea from the blood. | I71: Dialysis | J71: Kidney dialysis | K71: Minor | L71: hexOk is true but accepted 'Kidney dialysis' starts with K. | M71: Set hexOk false.
A72: aqa-bio-4.5-050 | B72: AQA | C72: Biology | D72: Separate and Combined | E72: Both | F72: Homeostasis and response | G72: 4.5.3.5 (Combined 4.5.3.4) | H72: How does a non-hormonal intrauterine device (IUD) prevent pregnancy? | I72: Prevents implantation of an embryo | J72: Stops embryo implanting; Prevents implantation; Kills or disables sperm; Stops sperm reaching the egg | K72: Minor | L72: hexOk is true but accepted 'Stops embryo implanting' and 'Kills or disables sperm' start with S and K. | M72: Set hexOk false.
A73: aqa-bio-4.5-051 | B73: AQA | C73: Biology | D73: Separate and Combined | E73: Higher only | F73: Homeostasis and response | G73: 4.5.3.6 (Combined 4.5.3.5) | H73: Which two hormones are given to a woman in a fertility drug? | I73: FSH and LH | J73: LH and FSH; Follicle stimulating hormone and luteinising hormone | K73: Minor | L73: hexOk is true but accepted 'LH and FSH' starts with L. The items can be given in any order. | M73: Set hexOk false.
A74: aqa-bio-4.5-052 | B74: AQA | C74: Biology | D74: Separate and Combined | E74: Higher only | F74: Homeostasis and response | G74: 4.5.3.6 (Combined 4.5.3.5) | H74: In IVF, where are the eggs fertilised by sperm? | I74: In the laboratory | J74: Laboratory; In a lab; Outside the body; In a dish | K74: Minor | L74: hexOk is true but stored answer 'In the laboratory' gives letter I, while accepted 'Laboratory', 'Outside the body' start with L and O. | M74: Set hexOk false, or make the answer 'Laboratory'.
A75: aqa-bio-4.5-053 | B75: AQA | C75: Biology | D75: Separate and Combined | E75: Higher only | F75: Homeostasis and response | G75: 4.5.3.6 (Combined 4.5.3.5) | H75: In IVF, why are only one or two embryos placed in the mother's uterus? | I75: Multiple births are risky | J75: To avoid multiple births; Reduce the risk of multiple births; Twins or triplets risk mother and babies | K75: Minor | L75: hexOk is true but accepted 'To avoid multiple births', 'Reduce the risk...', 'Twins or triplets...' start with other letters. | M75: Set hexOk false.
A76: aqa-bio-4.5-055 | B76: AQA | C76: Biology | D76: Separate and Combined | E76: Higher only | F76: Homeostasis and response | G76: 4.5.3.7 (Combined 4.5.3.6) | H76: What does thyroxine from the thyroid gland stimulate? | I76: Basal metabolic rate | J76: Metabolic rate; Metabolism | K76: Minor | L76: hexOk is true but accepted 'Metabolic rate' and 'Metabolism' start with M, not B. | M76: Set hexOk false.
A77: aqa-bio-4.5-063 | B77: AQA | C77: Biology | D77: Separate only | E77: Both | F77: Homeostasis and response | G77: 4.5.4.1 | H77: As well as length measurements, how should seedling results be recorded in this practical? | I77: Labelled biological drawings | J77: Labelled drawings; Biological drawings; Drawings | K77: Minor | L77: hexOk is true but accepted 'Biological drawings' and 'Drawings' start with B and D. | M77: Set hexOk false.
A78: aqa-bio-4.5-064 | B78: AQA | C78: Biology | D78: Separate only | E78: Both | F78: Homeostasis and response | G78: 4.5.4.1 | H78: In the seedling light investigation, why are all dishes kept at the same temperature? | I78: Temperature affects growth rate | J78: Temperature affects growth; Temperature affects germination; So only light affects growth | K78: Minor | L78: hexOk is true but accepted 'So only light affects growth' starts with S. | M78: Set hexOk false.
A79: aqa-bio-4.5-065 | B79: AQA | C79: Biology | D79: Separate only | E79: Both | F79: Homeostasis and response | G79: 4.5.4.1 | H79: A seedling is laid on its side in the dark. In which direction does its root grow? | I79: Downwards | J79: Down; Towards gravity; In the direction of gravity | K79: Minor | L79: hexOk is true but accepted 'Towards gravity' and 'In the direction of gravity' start with T and I. | M79: Set hexOk false.
...

Sheet Chemistry
A1: ID | B1: Board | C1: Subject | D1: Course | E1: Tier | F1: Topic | G1: Spec ref | H1: Question | I1: Answer | J1: Accepted answers | K1: Grade | L1: Reason | M1: Suggested fix | N1: Rob's decision | O1: Rob's note
A2: aqa-chem-4.7-071 | B2: AQA | C2: Chemistry | D2: Separate and Combined | E2: Both | F2: Organic chemistry | G2: 4.7.1.4 (Combined 5.7.1.4) | H2: Octane, C₈H₁₈, is cracked into hexane, C₆H₁₄, and one other product. Name it. | I2: Ethene | J2: C₂H₄ | K2: Doubtful | L2: Tagged Separate and Combined, but it asks students to NAME an individual alkene (ethene); the spec (4.7.1.4 / 5.7.1.4) says Combined Science students do not need to know the formulae or names of individual alkenes. C2H4 is accepted, so a Combined student could still score by deducing the formula. | M2: Reword to 'Give its formula' (answer C2H4, accept ethene), or tag Separate only.
A3: aqa-chem-4.1-009 | B3: AQA | C3: Chemistry | D3: Separate and Combined | E3: Both | F3: Atomic structure and the periodic table | G3: 4.1.1.3 (Combined 5.1.1.3) | H3: Which scientist suggested that electrons orbit the nucleus at specific distances? | I3: Niels Bohr | J3: Bohr | K3: Minor | L3: Hex letter is N (from 'Niels'), but nearly every student will answer 'Bohr', so the clue 'begins with N' is misleading. | M3: Make the answer 'Bohr' and accept 'Niels Bohr'.
A4: aqa-chem-4.1-011 | B4: AQA | C4: Chemistry | D4: Separate and Combined | E4: Both | F4: Atomic structure and the periodic table | G4: 4.1.1.3 (Combined 5.1.1.3) | H4: Which experiment showed that most of an atom's mass is in a tiny charged centre? | I4: Alpha particle scattering experiment | J4: Alpha scattering; Rutherford's scattering experiment; Gold foil experiment | K4: Minor | L4: Hex letter A, but 'Rutherford's (gold foil) experiment' and 'gold foil experiment' are very common correct answers that start with R or G. | M4: Set hexOk false, or keep the A clue and note the accepted alternatives are only for other games.
A5: aqa-chem-4.1-012 | B5: AQA | C5: Chemistry | D5: Separate and Combined | E5: Both | F5: Atomic structure and the periodic table | G5: 4.1.1.3 (Combined 5.1.1.3) | H5: In the scattering experiment, why were a few alpha particles deflected back? | I5: Repelled by a small, positive, massive nucleus | J5: Hit the concentrated positive nucleus; Bounced off a small dense positive nucleus | K5: Minor | L5: An explanation answer is used for Hex Hunt with letter R ('Repelled'); the accepted answers themselves start with H and B, so the letter clue does not fit the question. | M5: Set hexOk false.
A6: aqa-chem-4.1-025 | B6: AQA | C6: Chemistry | D6: Separate and Combined | E6: Both | F6: Atomic structure and the periodic table | G6: 4.1.1.7 (Combined 5.1.1.7) | H6: Which shells do electrons in an atom fill first? | I6: Innermost shells | J6: Lowest available energy levels; Lowest energy level; Shells closest to the nucleus | K6: Minor | L6: Hex letter I ('Innermost'), but the natural answers 'lowest energy levels' and 'the ones closest to the nucleus' (spec wording 'lowest available energy levels') start with L or C. | M6: Set hexOk false, or reword the answer to 'Lowest energy levels (innermost shells)'.
A7: aqa-chem-4.1-029 | B7: AQA | C7: Chemistry | D7: Separate and Combined | E7: Both | F7: Atomic structure and the periodic table | G7: 4.1.2.2 (Combined 5.1.2.2) | H7: Which scientist left gaps in his periodic table? | I7: Dmitri Mendeleev | J7: Mendeleev | K7: Minor | L7: Hex letter D (from 'Dmitri'); students will answer 'Mendeleev'. | M7: Make the answer 'Mendeleev' and accept 'Dmitri Mendeleev'.
A8: aqa-chem-4.1-034 | B8: AQA | C8: Chemistry | D8: Separate and Combined | E8: Both | F8: Atomic structure and the periodic table | G8: 4.1.2.3 (Combined 5.1.2.3) | H8: In which part of the periodic table are non-metals found? | I8: Right and top | J8: Top right; Right-hand side | K8: Minor | L8: Hex letter R from the unnatural order 'Right and top'; the usual answer is 'top right' (T). | M8: Make the answer 'Top right' (accept 'Towards the right and top', 'Right-hand side').
A9: aqa-chem-4.1-039 | B9: AQA | C9: Chemistry | D9: Separate and Combined | E9: Both | F9: Atomic structure and the periodic table | G9: 4.1.2.4 (Combined 5.1.2.4) | H9: Why are the noble gases unreactive? | I9: Stable arrangement of electrons | J9: Full outer shell; Stable electron arrangement | K9: Minor | L9: Hex letter S, but the most common correct answer is 'full outer shell' (F). | M9: Set hexOk false, or accept the letter mismatch knowingly.
A10: aqa-chem-4.1-044 | B10: AQA | C10: Chemistry | D10: Separate and Combined | E10: Both | F10: Atomic structure and the periodic table | G10: 4.1.2.5 (Combined 5.1.2.5) | H10: Why does reactivity increase going down Group 1? | I10: Outer electron further from nucleus, lost more easily | J10: Outer electron less strongly attracted to the nucleus | K10: Minor | L10: Two-clause explanation answer used on Hex Hunt with letter O; too long for the letter clue to be fair ('It has more shells...', 'Less attraction...' are equally right). | M10: Set hexOk false.
A11: aqa-chem-4.1-054 | B11: AQA | C11: Chemistry | D11: Separate only | E11: Both | F11: Atomic structure and the periodic table | G11: 4.1.3.2 | H11: Iron forms Fe²⁺ and Fe³⁺ ions. Which typical transition metal property does this show? | I11: Ions with different charges | J11: Forms more than one ion; Variable charges | K11: Minor | L11: Hex letter I, but the accepted answers start with F and V and 'variable charges/oxidation states' is a common correct answer. | M11: Set hexOk false.
A12: aqa-chem-4.1-055 | B12: AQA | C12: Chemistry | D12: Separate only | E12: Both | F12: Atomic structure and the periodic table | G12: 4.1.3.2 | H12: Why are cobalt and chromium compounds used to colour glass and pottery glazes? | I12: Transition metal compounds are coloured | J12: Coloured compounds; Transition metals form coloured compounds | K12: Minor | L12: Hex letter T, but the natural answer is 'they form coloured compounds' / 'coloured compounds' (C). | M12: Make the answer 'Coloured compounds' (accept 'Transition metal compounds are coloured').
A13: aqa-chem-4.10-007 | B13: AQA | C13: Chemistry | D13: Separate and Combined | E13: Both | F13: Using resources | G13: 4.10.1.2 (Combined 5.10.1.2) | H13: Apart from chlorine, name a sterilising agent used to treat drinking water. | I13: Ozone | J13: Ultraviolet light; UV light; UV | K13: Minor | L13: Two correct answers (ozone, ultraviolet light) but Hex Hunt shows only O, so a class answering 'UV light' is right but does not match the clue. | M13: Set hexOk false.
... A16: aqa-chem-4.10-028 | B16: AQA | C16: Chemistry | D16: Separate only | E16: Both | F16: Using resources | G16: 4.10.3.1 | H16: Which two substances must both be present for iron to rust? | I16: Air and water | J16: Oxygen and water | K16: Minor | L16: Two-item answer: other orders ('Water and air', 'Water and oxygen') are not accepted, and the common answer 'water and oxygen' does not match the A clue. | M16: Accept either order; set hexOk false.
A17: aqa-chem-4.10-034 | B17: AQA | C17: Chemistry | D17: Separate only | E17: Both | F17: Using resources | G17: 4.10.3.2 | H17: Stainless steel contains iron and which two other metals? | I17: Chromium and nickel | K17: Minor | L17: Two-item answer: 'Nickel and chromium' is not accepted. | M17: Add 'Nickel and chromium' to accepted answers.
A18: aqa-chem-4.2-006 | B18: AQA | C18: Chemistry | D18: Separate and Combined | E18: Both | F18: Bonding, structure, and the properties of matter | G18: 4.2.1.2 (Combined 5.2.1.2) | H18: When a metal atom reacts with a non-metal atom, what happens to the electrons in the metal atom's outer shell? | I18: Transferred to the non-metal atom | J18: Lost to the non-metal; Given to the non-metal | K18: Minor | L18: Hex letter T ('Transferred'), but 'they are lost (to the non-metal)' is an equally common correct answer and is already accepted (L). | M18: Set hexOk false, or accept the T clue knowingly.
A19: aqa-chem-4.2-017 | B19: AQA | C19: Chemistry | D19: Separate and Combined | E19: Both | F19: Bonding, structure, and the properties of matter | G19: 4.2.1.3 (Combined 5.2.1.3) | H19: Give one limitation of using a ball and stick model to show the structure of sodium chloride. | I19: Shows gaps between the ions | J19: Ions are really touching; Bonds are not sticks; Forces shown as sticks are not real; Ions not to scale; Shows only a small part of the lattice | K19: Minor | L19: Open 'give one limitation' question with five different accepted answers is on Hex Hunt with letter S; most correct answers do not start with S. | M19: Set hexOk false.
A20: aqa-chem-4.2-034 | B20: AQA | C20: Chemistry | D20: Separate and Combined | E20: Higher only | F20: Bonding, structure, and the properties of matter | G20: 4.2.2.1 (Combined 5.2.2.1) | H20: Apart from missing forces, give one limitation of showing particles as small solid spheres. | I20: Particles are not all spherical | J20: Particles are not solid; Particles are not hard spheres; Spheres are inelastic but real particles are not | K20: Minor | L20: Open 'give one limitation' question on Hex Hunt (letter P); accepted answers vary. The accepted answer 'Spheres are inelastic but real particles are not' is confused (the spec calls the model's spheres inelastic; it is not a clear limitation in that form). | M20: Set hexOk false; replace that accepted answer with 'Particles are not solid inelastic spheres'.
A21: aqa-chem-4.2-052 | B21: AQA | C21: Chemistry | D21: Separate and Combined | E21: Both | F21: Bonding, structure, and the properties of matter | G21: 4.2.2.5 (Combined 5.2.2.5) | H21: Why are polymers solid at room temperature? | I21: Relatively strong intermolecular forces | J21: Strong forces between polymer molecules; Strong intermolecular forces | K21: Minor | L21: Hex letter R from 'Relatively'; students will write 'strong intermolecular forces' (S), which is accepted. | M21: Make the answer 'Strong intermolecular forces' (accept 'Relatively strong intermolecular forces').
A22: aqa-chem-4.2-072 | B22: AQA | C22: Chemistry | D22: Separate and Combined | E22: Both | F22: Bonding, structure, and the properties of matter | G22: 4.2.3.2 (Combined 5.2.3.2) | H22: Why is graphite soft and slippery? | I22: Layers slide; no covalent bonds between them | J22: Layers can slide over each other; No covalent bonds between layers; Weak forces between layers | K22: Minor | L22: Two-part explanation answer on Hex Hunt (letter L); accepted answers start with N and W. | M22: Set hexOk false.
A23: aqa-chem-4.2-087 | B23: AQA | C23: Chemistry | D23: Separate only | E23: Both | F23: Bonding, structure, and the properties of matter | G23: 4.2.4.2 | H23: Name one cosmetic or personal-care product that may contain nanoparticles. | I23: Sun cream | J23: Sunscreen; Deodorant; Cosmetics; Make-up | K23: Minor | L23: 'Name one product' with several accepted answers (deodorant, cosmetics, make-up) is on Hex Hunt with letter S. | M23: Set hexOk false.
A24: aqa-chem-4.2-088 | B24: AQA | C24: Chemistry | D24: Separate only | E24: Both | F24: Bonding, structure, and the properties of matter | G24: 4.2.4.2 | H24: Give one advantage of nanoparticles over normal-sized particles of the same material. | I24: Smaller quantities needed | J24: Less material needed; More effective; Higher surface area to volume ratio | K24: Minor | L24: 'Give one advantage' with varied accepted answers is on Hex Hunt with letter S. | M24: Set hexOk false.
A25: aqa-chem-4.2-089 | B25: AQA | C25: Chemistry | D25: Separate only | E25: Both | F25: Bonding, structure, and the properties of matter | G25: 4.2.4.2 | H25: Give one possible risk of using nanoparticles in products such as sun cream. | I25: Long-term health effects unknown | J25: May enter body cells and cause harm; May be toxic; May harm the environment | K25: Minor | L25: 'Give one possible risk' with varied accepted answers is on Hex Hunt with letter L. | M25: Set hexOk false.
A26: aqa-chem-4.3-053 | B26: AQA | C26: Chemistry | D26: Separate and Combined | E26: Both | F26: Quantitative chemistry | G26: 4.3.1.1 (Combined 5.3.1.1) | H26: Which law says that no atoms are lost or made during a chemical reaction? | I26: Conservation of mass | J26: Law of conservation of mass | K26: Minor | L26: Near-identical to aqa-chem-4.3-001 (same law, same answer 'Conservation of mass'). | M26: Remove, or replace with a different conservation-of-mass question (e.g. a mass-balance calculation).
A27: aqa-chem-4.3-056 | B27: AQA | C27: Chemistry | D27: Separate and Combined | E27: Both | F27: Quantitative chemistry | G27: 4.3.1.3 (Combined 5.3.1.3) | H27: Calcium carbonate is heated in an open tube and its mass goes down. Which gas escapes? | I27: Carbon dioxide | J27: CO₂ | K27: Minor | L27: Near-duplicate of aqa-chem-4.3-011 (carbonate heated, which gas escapes: carbon dioxide). | M27: Remove, or change to ask why the mass goes down.
A28: aqa-chem-4.3-057 | B28: AQA | C28: Chemistry | D28: Separate and Combined | E28: Both | F28: Quantitative chemistry | G28: 4.3.1.4 (Combined 5.3.1.4) | H28: Repeat measurements spread around the mean. What word describes how unsure the result is? | I28: Uncertainty | K28: Minor | L28: Near-duplicate of aqa-chem-4.3-014: both ask for the word 'Uncertainty'. | M28: Remove, or replace with a different measurement question.
A29: aqa-chem-4.4-009 | B29: AQA | C29: Chemistry | D29: Separate and Combined | E29: Both | F29: Chemical changes | G29: 4.4.1.3 (Combined 5.4.1.3) | H29: Name an unreactive metal found in the Earth as the metal itself. | I29: Gold | J29: Au; Platinum; Silver | K29: Minor | L29: 'Name an unreactive metal' accepts gold, platinum and silver but Hex Hunt shows the letter G, so it only works if the class thinks of gold. | M29: Set hexOk false, or reword to the spec example ('Which unreactive yellow metal is found as the metal itself?').
A30: aqa-chem-4.4-024 | B30: AQA | C30: Chemistry | D30: Separate and Combined | E30: Both | F30: Chemical changes | G30: 4.4.2.3 (Combined 5.4.2.3) | H30: When making copper sulfate, what shows that enough copper oxide has been added? | I30: Black solid stays undissolved | J30: Solid no longer dissolves; Excess solid left at the bottom; Some solid remains; No more solid reacts | K30: Minor | L30: Hex letter B ('Black solid stays undissolved') while the natural answers ('some solid is left', 'excess solid', 'no more dissolves') start with S, E or N. | M30: Set hexOk false.
A31: aqa-chem-4.4-031 | B31: AQA | C31: Chemistry | D31: Separate only | E31: Both | F31: Chemical changes | G31: 4.4.2.5 | H31: Why is universal indicator not used in a titration? | I31: Gradual colour change, no sharp end point | J31: Colour changes gradually; No single clear colour change | K31: Minor | L31: Explanation answer on Hex Hunt (letter G); accepted answers start with C and N. | M31: Set hexOk false.
A32: aqa-chem-4.4-036 | B32: AQA | C32: Chemistry | D32: Separate and Combined | E32: Higher only | F32: Chemical changes | G32: 4.4.2.6 (Combined 5.4.2.5) | H32: The pH of an acid falls from 4 to 2. By what factor does the hydrogen ion concentration change? | I32: Increases 100 times | J32: 100; ×100; Factor of 100; 100 times greater | K32: Minor | L32: Numerical answer ('Increases 100 times') is on Hex Hunt with letter I; most students will simply write '100' or '100 times'. | M32: Set hexOk false (consider calcTag true: 10 to the power of the pH change).
A33: aqa-chem-4.4-047 | B33: AQA | C33: Chemistry | D33: Separate and Combined | E33: Both | F33: Chemical changes | G33: 4.4.3.3 (Combined 5.4.3.3) | H33: Why must the positive electrodes be replaced regularly in aluminium extraction? | I33: Carbon anode reacts with oxygen | J33: Anode burns away; Oxygen reacts with the carbon anode; Carbon reacts with oxygen to form carbon dioxide | K33: Minor | L33: Explanation answer on Hex Hunt (letter C); accepted answers start with A and O ('the anode burns away' is the commonest). | M33: Set hexOk false.
A34: aqa-chem-4.5-006 | B34: AQA | C34: Chemistry | D34: Separate and Combined | E34: Both | F34: Energy changes | G34: 4.5.1.1 (Combined 5.5.1.1) | H34: Name one everyday product that uses an exothermic reaction to warm something up. | I34: Hand warmer | J34: Hand warmers; Self-heating can; Self-heating cans | K34: Minor | L34: 'Name one everyday product' with two spec answers (hand warmer, self-heating can) is on Hex Hunt with letter H. | M34: Set hexOk false, or reword to point at hand warmers only.
A35: aqa-chem-4.5-012 | B35: AQA | C35: Chemistry | D35: Separate and Combined | E35: Both | F35: Energy changes | G35: 4.5.1.1 (Combined 5.5.1.1) | H35: Why must a self-heating can use an exothermic reaction rather than an endothermic one? | I35: Exothermic reactions release energy, raising the temperature | J35: Transfers energy to surroundings; Heats the food; Temperature increases | K35: Minor | L35: Long explanation answer on Hex Hunt (letter E); accepted answers start with T and H. | M35: Set hexOk false.
A36: aqa-chem-4.5-018 | B36: AQA | C36: Chemistry | D36: Separate and Combined | E36: Both | F36: Energy changes | G36: 4.5.1.1 (Combined 5.5.1.1) | H36: Why should the student stir the mixture before reading the temperature? | I36: Even temperature throughout the mixture | J36: Mixes reactants evenly; So the temperature is the same throughout; Makes reading accurate | K36: Minor | L36: Explanation answer on Hex Hunt (letter E); accepted answers start with M and S, and 'so the temperature is the same throughout' is the common answer. | M36: Set hexOk false.
A37: aqa-chem-4.5-024 | B37: AQA | C37: Chemistry | D37: Separate and Combined | E37: Both | F37: Energy changes | G37: 4.5.1.2 (Combined 5.5.1.2) | H37: On a reaction profile, the activation energy is measured from the reactants to which point? | I37: Peak of the curve | J37: Top of the curve; Highest point; Maximum of the curve; Top of the hump | K37: Minor | L37: Hex letter P ('Peak') while 'top of the curve' and 'highest point' are equally common and accepted. | M37: Set hexOk false.
A38: aqa-chem-4.5-038 | B38: AQA | C38: Chemistry | D38: Separate only | E38: Both | F38: Energy changes | G38: 4.5.2.1 | H38: How can a rechargeable cell be recharged? | I38: Supply an external electric current | J38: Connect to an external current; Pass a current through it; Plug into a charger | K38: Minor | L38: Explanation answer on Hex Hunt (letter S, 'Supply...'); accepted answers start with C and P. | M38: Set hexOk false.
A39: aqa-chem-4.5-042 | B39: AQA | C39: Chemistry | D39: Separate only | E39: Both | F39: Energy changes | G39: 4.5.2.2 | H39: In a fuel cell, hydrogen is oxidised electrochemically to produce what? | I39: Potential difference | J39: Voltage; Electricity; Electric current; pd | K39: Minor | L39: Hex letter P ('Potential difference'), but 'electricity' and 'voltage' are common correct answers and are accepted. | M39: Set hexOk false, or accept the P clue knowingly (it matches the spec wording).
A40: aqa-chem-4.6-013 | B40: AQA | C40: Chemistry | D40: Separate and Combined | E40: Both | F40: The rate and extent of chemical change | G40: 4.6.1.2 (Combined 5.6.1.2) | H40: In the gas collection practical, why does the volume of gas produced each second fall as the reaction goes on? | I40: Reactants are used up | J40: Acid concentration decreases; Acid is used up; Concentration of reactants falls; Fewer collisions per second; Less magnesium left | K40: Minor | L40: Explanation answer with five varied accepted answers is on Hex Hunt with letter R. | M40: Set hexOk false.
A41: aqa-chem-4.6-014 | B41: AQA | C41: Chemistry | D41: Separate and Combined | E41: Both | F41: The rate and extent of chemical change | G41: 4.6.1.3 (Combined 5.6.1.3) | H41: What is the minimum amount of energy that colliding particles must have to react called? | I41: Activation energy | K41: Minor | L41: Duplicate across packs: aqa-chem-4.5-019 asks the same question ('minimum energy that colliding particles must have to react', answer Activation energy). | M41: Remove one of the pair, or change this one to a different collision-theory question.
A42: aqa-chem-4.6-015 | B42: AQA | C42: Chemistry | D42: Separate and Combined | E42: Both | F42: The rate and extent of chemical change | G42: 4.6.1.3 (Combined 5.6.1.3) | H42: According to collision theory, what must reacting particles do for a reaction to happen? | I42: Collide with sufficient energy | J42: Collide with at least the activation energy; Collide with enough energy | K42: Minor | L42: Near-duplicate across packs of aqa-chem-4.5-021 (conditions for particles to react: collide with sufficient energy). | M42: Remove one of the pair, or reword this one (e.g. 'Why do most collisions not lead to a reaction?').
...

Sheet Physics
A1: ID | B1: Board | C1: Subject | D1: Course | E1: Tier | F1: Topic | G1: Spec ref | H1: Question | I1: Answer | J1: Accepted answers | K1: Grade | L1: Reason | M1: Suggested fix | N1: Rob's decision | O1: Rob's note
A2: aqa-phys-4.3-048 | B2: AQA | C2: Physics | D2: Separate and Combined | E2: Both | F2: Particle model of matter | G2: 4.3.3.1 (Combined 6.3.3.1) | H2: What is the name of the temperature scale that starts at absolute zero? | I2: Kelvin | K2: Wrong | L2: Off the specification: neither 8463 nor 8464 mentions the kelvin scale or absolute zero (the Kelvin scale was in the legacy specification, not this one); 4.3.3.1 only relates temperature to average kinetic energy. | M2: Remove, or replace with an on-spec 4.3.3.1 question, e.g. 'The temperature of a gas is related to the average of which energy of its molecules?' (but see 4.3-032, which already asks this).
A3: aqa-phys-4.6-010 | B3: AQA | C3: Physics | D3: Separate and Combined | E3: Both | F3: Waves | G3: 4.6.1.2 (Combined 6.6.1.2) | H3: Sound passes from air into water, where it travels faster. What happens to its wavelength? | I3: Increases | J3: Gets longer; Longer | K3: Wrong | L3: Tagged Separate and Combined, but how velocity, frequency and wavelength are inter-related when sound passes from one medium to another is a '(Physics only)' statement in 8463 4.6.1.2 and is absent from Trilogy 6.6.1.2. | M3: Tag Separate only (add 'Sep: yes'). The physics and answer are correct.
A4: aqa-phys-4.7-020 | B4: AQA | C4: Physics | D4: Separate and Combined | E4: Both | F4: Magnetism and electromagnetism | G4: 4.7.2.1 (Combined 6.7.2.1) | H4: In an electric bell or relay, why is an electromagnet used instead of a permanent magnet? | I4: Can be switched on and off | J4: Magnetism can be turned off; Switched off when current stops | K4: Wrong | L4: Tagged Separate and Combined, but explaining how electromagnetic devices such as bells and relays work is the '(Physics only)' statement in 8463 4.7.2.1; Trilogy 6.7.2.1 has no device content. | M4: Tag Separate only (add 'Sep: yes'); the answer itself is fine.
A5: edexcel-phys-3-050 | B5: Edexcel | C5: Physics | D5: Separate and Combined | E5: Both | F5: Conservation of energy | G5: 3.2 | H5: What energy store does an object raised above the ground have? | I5: Gravitational potential energy | J5: Gravitational potential | K5: Wrong | L5: Ref 3.2 is the kinetic energy equation; a raised object's GPE store belongs to 3.1. Also near-duplicate of edexcel-phys-8-060. (Graded Wrong: a wrong specification reference is a wrong tag.) | M5: Change Ref to 3.1 (or 3.5); consider removing as a duplicate.
A6: edexcel-phys-3-051 | B6: Edexcel | C6: Physics | D6: Separate and Combined | E6: Both | F6: Conservation of energy | G6: 3.1 | H6: What energy store do moving objects have? | I6: Kinetic energy | J6: Kinetic | K6: Wrong | L6: Ref 3.1 is the GPE equation; the kinetic store belongs to 3.2. Also near-duplicate of edexcel-phys-8-061. (Graded Wrong: a wrong specification reference is a wrong tag.) | M6: Change Ref to 3.2; consider removing as a duplicate.
A7: edexcel-phys-8-058 | B7: Edexcel | C7: Physics | D7: Separate and Combined | E7: Both | F7: Energy – forces doing work | G7: 8.5 | H7: What force opposes motion between two surfaces in contact? | I7: Friction | K7: Wrong | L7: Ref 8.5 is measuring work done; 'what force opposes motion between surfaces' is 9.1b (contact forces including friction). (Graded Wrong: a wrong specification reference is a wrong tag.) | M7: Change Ref to 9.1 (or remove, as it is generic).
A8: edexcel-phys-8-060 | B8: Edexcel | C8: Physics | D8: Separate and Combined | E8: Both | F8: Energy – forces doing work | G8: 8.9 | H8: What energy store does an object gain when it is lifted? | I8: Gravitational potential energy | J8: Gravitational potential | K8: Wrong | L8: Ref 8.9 is the kinetic energy equation; GPE belongs to 8.8 (or 8.1). Near-duplicate of edexcel-phys-8-001 and edexcel-phys-3-050. (Graded Wrong: a wrong specification reference is a wrong tag.) | M8: Change Ref to 8.8, or remove as a duplicate.
A9: edexcel-phys-8-061 | B9: Edexcel | C9: Physics | D9: Separate and Combined | E9: Both | F9: Energy – forces doing work | G9: 8.8 | H9: What name is given to the energy of a moving object? | I9: Kinetic energy | J9: Kinetic | K9: Wrong | L9: Ref 8.8 is the GPE equation; kinetic energy belongs to 8.9. Near-duplicate of edexcel-phys-8-065 and edexcel-phys-3-051. (Graded Wrong: a wrong specification reference is a wrong tag.) | M9: Change Ref to 8.9, or remove as a duplicate.
A10: edexcel-phys-8-065 | B10: Edexcel | C10: Physics | D10: Separate and Combined | E10: Both | F10: Energy – forces doing work | G10: 8.4 | H10: What type of energy store does a moving car have? | I10: Kinetic energy store | J10: Kinetic | K10: Wrong | L10: Ref 8.4 is about ways energy is transferred (work, electrically, heating), not stores; a moving car's kinetic store fits 8.1. (Graded Wrong: a wrong specification reference is a wrong tag.) | M10: Change Ref to 8.1.
A11: edexcel-phys-8-066 | B11: Edexcel | C11: Physics | D11: Separate and Combined | E11: Both | F11: Energy – forces doing work | G11: 8.4 | H11: What type of energy store is released when fuel is burned in an engine? | I11: Chemical energy store | J11: Chemical | K11: Wrong | L11: Ref 8.4 is about ways energy is transferred, not stores; fuel's chemical store fits 8.1. Near-duplicate of edexcel-phys-8-002. (Graded Wrong: a wrong specification reference is a wrong tag.) | M11: Change Ref to 8.1.
A12: aqa-phys-4.3-051 | B12: AQA | C12: Physics | D12: Separate and Combined | E12: Both | F12: Particle model of matter | G12: 4.3.3.1 (Combined 6.3.3.1) | H12: How do gas particles move between collisions? | I12: In straight lines | J12: Straight lines | K12: Doubtful | L12: Straight-line motion between collisions is sound kinetic theory but is not in the 4.3.3.1 statement, which says only 'constant random motion'; students taught to the specification may not have met it. | M12: Rob to decide; keep only if happy to go beyond the spec wording, otherwise remove.
A13: aqa-phys-4.7-054 | B13: AQA | C13: Physics | D13: Separate and Combined | E13: Both | F13: Magnetism and electromagnetism | G13: 4.7.2.1 (Combined 6.7.2.1) | H13: Why is the core of an electromagnet made of iron rather than steel? | I13: Iron loses its magnetism quickly | J13: Iron is an induced magnet; Iron demagnetises when switched off | K13: Doubtful | L13: Iron versus steel cores (soft versus hard magnetic materials) is not in 4.7.2.1 or Trilogy 6.7.2.1, which only say an electromagnet has an iron core; steel is listed as a magnetic material without this distinction. Combined students may not have met it. | M13: Rob to decide; either tag Separate only (link to 4.7.3.4 'iron is used as it is easily magnetised') or remove.
A14: edexcel-phys-10-058 | B14: Edexcel | C14: Physics | D14: Separate and Combined | E14: Both | F14: Electricity and circuits | G14: 10.17 | H14: In the filament lamp practical, why should the circuit be switched off between readings? | I14: To stop the filament heating up | J14: Keep the temperature constant; resistance changes with temperature; to avoid overheating | K14: Doubtful | L14: In the filament lamp investigation the filament is meant to heat up (that is why its resistance rises), so 'to stop the filament heating up' is a muddled reason; switching off between readings is to keep a fixed resistor (and the wires) from warming and changing resistance. | M14: Reword to 'In the resistor practical, why should the circuit be switched off between readings?' Answer: To stop the resistor heating up. Accept: Keep its temperature constant; so its resistance stays the same.
A15: edexcel-phys-9-046 | B15: Edexcel | C15: Physics | D15: Separate and Combined | E15: Higher only | F15: Forces and their effects | G15: 9.3 | H15: A 10 N force acts at 30° above the horizontal. About how large is its horizontal component? | I15: About 8.7 N | J15: 8.7 N; 9 N; 8.66 N | K15: Doubtful | L15: 9.3 limits resolution to scale drawings only; finding 10 cos 30° in a quick-fire round needs trigonometry, which is beyond the GCSE physics statement, and is not practical as a scale drawing on a whiteboard. | M15: Remove, or reword as a scale-drawing estimate with a wider tolerance (e.g. 'about 9 N'), or use a 3-4-5 style case.
A16: aqa-phys-4.1-018 | B16: AQA | C16: Physics | D16: Separate and Combined | E16: Both | F16: Energy | G16: 4.1.1.2 (Combined 6.1.1.2) | H16: A car's speed doubles. By what factor does its kinetic energy increase? | I16: Four times | J16: 4; ×4; Quadruples | K16: Minor | L16: hexOk is true but the answer is a number; most students will write '4' or 'x4' (or 'quadruples'), so the letter F does not match common correct answers. It is also a proportional-reasoning calculation without a calc tag. | M16: Set hexOk false; consider calcTag true.
A17: aqa-phys-4.1-032 | B17: AQA | C17: Physics | D17: Separate and Combined | E17: Both | F17: Energy | G17: 4.1.1.4 (Combined 6.1.1.4) | H17: Two motors lift the same load through the same height. Motor A takes 5 s and motor B takes 10 s. How many times more powerful is A? | I17: Twice | J17: 2; Two times; Double | K17: Minor | L17: hexOk is true but the answer is a number; students will write '2', 'double' or 'twice', which start with different letters. | M17: Set hexOk false; consider calcTag true.
A18: aqa-phys-4.1-038 | B18: AQA | C18: Physics | D18: Separate and Combined | E18: Both | F18: Energy | G18: 4.1.2.1 (Combined 6.1.2.1) | H18: What happens to the rate of energy transfer by conduction through a material with a higher thermal conductivity? | I18: Higher rate | J18: Increases; Faster; Higher | K18: Minor | L18: hexOk is true but the natural answer to 'what happens to the rate' is 'it increases', not 'Higher rate', so the letter H does not match common correct answers. | M18: Set hexOk false (or reword to 'Is the rate higher or lower?').
A19: aqa-phys-4.1-039 | B19: AQA | C19: Physics | D19: Separate and Combined | E19: Both | F19: Energy | G19: 4.1.2.1 (Combined 6.1.2.1) | H19: How do thicker walls with a lower thermal conductivity affect the rate of cooling of a house? | I19: Slower rate of cooling | J19: Slower; Decreases; Lower; Reduces it | K19: Minor | L19: hexOk is true but common correct answers start 'Decreases', 'Lower', 'Reduces' or 'Slower', so the letter S is not reliable. | M19: Set hexOk false.
... A43: aqa-phys-4.3-039 | B43: AQA | C43: Physics | D43: Separate only | E43: Higher only | F43: Particle model of matter | G43: 4.3.3.3 | H43: What is meant by work, in terms of energy and force? | I43: Energy transferred by a force | J43: Transfer of energy by a force; Energy transfer by a force | K43: Minor | L43: hexOk is true but the specification's own wording 'Transfer of energy by a force' (accepted) starts with T, not E. | M43: Set hexOk false.
A44: aqa-phys-4.3-044 | B44: AQA | C44: Physics | D44: Separate and Combined | E44: Both | F44: Particle model of matter | G44: 4.3.1.2 (Combined 6.3.1.2) | H44: What is the change of state from solid straight to gas called? | I44: Sublimation | K44: Minor | L44: Duplicate of aqa-phys-4.3-012 in the same pack ('change of state directly from solid to gas' / 'solid straight to gas', both Sublimation). | M44: Remove one of the two.
A45: aqa-phys-4.4-003 | B45: AQA | C45: Physics | D45: Separate and Combined | E45: Both | F45: Atomic structure | G45: 4.4.1.1 (Combined 6.4.1.1) | H45: An electron absorbs electromagnetic radiation. How does its position in the atom change? | I45: Higher energy level, further from nucleus | J45: Moves to a higher energy level; Moves further from the nucleus | K45: Minor | L45: hexOk is true on a description; 'Moves further from the nucleus' (accepted, and the spec's own wording) starts with M, not H. | M45: Set hexOk false.
A46: aqa-phys-4.4-011 | B46: AQA | C46: Physics | D46: Separate and Combined | E46: Both | F46: Atomic structure | G46: 4.4.1.3 (Combined 6.4.1.3) | H46: Which scientist provided the evidence that neutrons exist in the nucleus? | I46: James Chadwick | J46: Chadwick | K46: Minor | L46: hexOk is true but most students will write just 'Chadwick' (accepted), which starts with C, not J. | M46: Set hexOk false, or make the stored answer 'Chadwick' with 'James Chadwick' accepted.
A47: aqa-phys-4.4-017 | B47: AQA | C47: Physics | D47: Separate and Combined | E47: Both | F47: Atomic structure | G47: 4.4.2.1 (Combined 6.4.2.1) | H47: What is a beta particle? | I47: High-speed electron from the nucleus | J47: Fast electron; Electron emitted from the nucleus | K47: Minor | L47: hexOk is true but common correct answers start 'Fast electron', 'An electron' or 'Electron from the nucleus', not H. | M47: Set hexOk false.
A48: aqa-phys-4.4-021 | B48: AQA | C48: Physics | D48: Separate and Combined | E48: Both | F48: Atomic structure | G48: 4.4.2.2 (Combined 6.4.2.2) | H48: A nucleus with mass number 226 and atomic number 88 emits an alpha particle. What are the new mass number and atomic number? | I48: Mass number 222, atomic number 86 | J48: 222 and 86 | K48: Minor | L48: hexOk is true on a numerical answer (students will write '222 and 86'), and the arithmetic (226 - 4, 88 - 2) is a calculation without a calc tag. | M48: Set hexOk false and calcTag true.
A49: aqa-phys-4.4-022 | B49: AQA | C49: Physics | D49: Separate and Combined | E49: Both | F49: Atomic structure | G49: 4.4.2.2 (Combined 6.4.2.2) | H49: A nucleus with mass number 14 and atomic number 6 emits a beta particle. What are the new mass number and atomic number? | I49: Mass number 14, atomic number 7 | J49: 14 and 7 | K49: Minor | L49: hexOk is true on a numerical answer (students will write '14 and 7'), and the balancing is a calculation without a calc tag. | M49: Set hexOk false and calcTag true.
A50: aqa-phys-4.4-026 | B50: AQA | C50: Physics | D50: Separate and Combined | E50: Higher only | F50: Atomic structure | G50: 4.4.2.3 (Combined 6.4.2.3) | H50: After three half-lives, what is the ratio of the final count rate to the initial count rate? | I50: 1:8 | J50: 1/8; One eighth; 0.125 | K50: Minor | L50: Calculating the ratio after three half-lives ((1/2)^3) is a calculation, but calcTag is false. | M50: Set calcTag true.
A51: aqa-phys-4.4-029 | B51: AQA | C51: Physics | D51: Separate and Combined | E51: Both | F51: Atomic structure | G51: 4.4.2.4 (Combined 6.4.2.4) | H51: Why should findings about the effects of radiation on humans be published and shared? | I51: Peer review | J51: So other scientists can check them; To be checked by other scientists | K51: Minor | L51: 'Peer review' does not grammatically answer 'Why...?'; the natural answer 'So other scientists can check them' (accepted) starts with S, so hexOk is unreliable. | M51: Set hexOk false, or reword to 'Findings on radiation and humans are shared so they can be checked by what process?' A: Peer review.
A52: aqa-phys-4.4-040 | B52: AQA | C52: Physics | D52: Separate only | E52: Both | F52: Atomic structure | G52: 4.4.3.3 | H52: What is the main risk to a patient of medical uses of nuclear radiation? | I52: Damage to healthy cells | J52: Healthy cells damaged; Could cause cancer; Mutations in healthy cells | K52: Minor | L52: hexOk is true but 'Could cause cancer' (accepted) and 'Mutations' start with different letters. | M52: Set hexOk false.
A53: aqa-phys-4.4-042 | B53: AQA | C53: Physics | D53: Separate only | E53: Both | F53: Atomic structure | G53: 4.4.4.1 | H53: What is the splitting of a large, unstable nucleus called? | I53: Nuclear fission | J53: Fission | K53: Minor | L53: hexOk is true but many students will write just 'Fission' (accepted), which starts with F, not N. | M53: Set hexOk false, or store 'Fission' with 'Nuclear fission' accepted.
A54: aqa-phys-4.4-043 | B54: AQA | C54: Physics | D54: Separate only | E54: Both | F54: Atomic structure | G54: 4.4.4.1 | H54: Name one element used as fuel in nuclear fission reactors. | I54: Uranium | J54: Plutonium | K54: Minor | L54: hexOk is true but uranium and plutonium are both correct (the spec names both), so the letter U is only right for one. | M54: Set hexOk false.
A55: aqa-phys-4.4-046 | B55: AQA | C55: Physics | D55: Separate only | E55: Both | F55: Atomic structure | G55: 4.4.4.1 | H55: How does the chain reaction in a nuclear reactor differ from that in a nuclear weapon? | I55: Reactor controlled, weapon uncontrolled | J55: Controlled in a reactor; Uncontrolled in a weapon | K55: Minor | L55: hexOk is true on a comparison; answers start 'Controlled...', 'Uncontrolled...', 'In a reactor...', not reliably R. | M55: Set hexOk false.
